Workbook

Sheet 2017
A1: Number | B1: Day | C1: Steps | D1: Difference
A2: 1 | B2: 13.7.2017 | C2: 91 | F2: July | J2: July
A3: 2 | B3: 14.7.2017 | C3: 2515 | D3: =Table1[[#This Row],[Steps]]-C2 -> 2424
A4: 3 | B4: 15.7.2017 | C4: 6800 | D4: =Table1[[#This Row],[Steps]]-C3 -> 4285 | F4: Mean | G4: 2823.6316 | J4: Mean | K4: 2823.6316
A5: 4 | B5: 16.7.2017 | C5: 358 | D5: =Table1[[#This Row],[Steps]]-C4 -> -6442 | F5: Standard Error | G5: 822.12139 | J5: Standard Error | K5: 822.12139
A6: 5 | B6: 17.7.2017 | C6: 170 | D6: =Table1[[#This Row],[Steps]]-C5 -> -188 | F6: Median | G6: 1968 | J6: Median | K6: 1968
A7: 6 | B7: 18.7.2017 | C7: 193 | D7: =Table1[[#This Row],[Steps]]-C6 -> 23 | F7: Mode | G7: =#N/A -> #N/A | J7: Mode | K7: =#N/A -> #N/A
A8: 7 | B8: 19.7.2017 | C8: 1968 | D8: =Table1[[#This Row],[Steps]]-C7 -> 1775 | F8: Standard Deviation | G8: 3583.544 | J8: Standard Deviation | K8: 3583.544
A9: 8 | B9: 20.7.2017 | C9: 2709 | D9: =Table1[[#This Row],[Steps]]-C8 -> 741 | F9: Sample Variance | G9: 12841788 | J9: Sample Variance | K9: 12841788
A10: 9 | B10: 21.7.2017 | C10: 8200 | D10: =Table1[[#This Row],[Steps]]-C9 -> 5491 | F10: Kurtosis | G10: 4.5301972 | J10: Kurtosis | K10: 4.5301972
A11: 10 | B11: 22.7.2017 | C11: 2934 | D11: =Table1[[#This Row],[Steps]]-C10 -> -5266 | F11: Skewness | G11: 2.0349485 | J11: Skewness | K11: 2.0349485
A12: 11 | B12: 23.7.2017 | C12: 1773 | D12: =Table1[[#This Row],[Steps]]-C11 -> -1161 | F12: Range | G12: 13935 | J12: Range | K12: 13935
A13: 12 | B13: 24.7.2017 | C13: 530 | D13: =Table1[[#This Row],[Steps]]-C12 -> -1243 | F13: Minimum | G13: 91 | J13: Minimum | K13: 91
A14: 13 | B14: 25.7.2017 | C14: 2967 | D14: =Table1[[#This Row],[Steps]]-C13 -> 2437 | F14: Maximum | G14: 14026 | J14: Maximum | K14: 14026
A15: 14 | B15: 26.7.2017 | C15: 1989 | D15: =Table1[[#This Row],[Steps]]-C14 -> -978 | F15: Sum | G15: 53649 | J15: Sum | K15: 53649
A16: 15 | B16: 27.7.2017 | C16: 522 | D16: =Table1[[#This Row],[Steps]]-C15 -> -1467 | F16: Count | G16: 19 | J16: Count | K16: 19
A17: 16 | B17: 28.7.2017 | C17: 14026 | D17: =Table1[[#This Row],[Steps]]-C16 -> 13504 | F17: Largest(1) | G17: 14026 | J17: Largest(1) | K17: 14026
A18: 17 | B18: 29.7.2017 | C18: 179 | D18: =Table1[[#This Row],[Steps]]-C17 -> -13847 | F18: Smallest(1) | G18: 91 | J18: Smallest(1) | K18: 91
A19: 18 | B19: 30.7.2017 | C19: 293 | D19: =Table1[[#This Row],[Steps]]-C18 -> 114 | F19: Confidence Level(95.0%) | G19: 1727.2129 | J19: Confidence Level(95.0%) | K19: 1727.2129
A20: 19 | B20: 31.7.2017 | C20: 5432 | D20: =Table1[[#This Row],[Steps]]-C19 -> 5139
A21: 1 | B21: 1.8.2017 | C21: 2696 | D21: =Table1[[#This Row],[Steps]]-C20 -> -2736 | F21: August | J21: July-August
A22: 2 | B22: 2.8.2017 | C22: 1796 | D22: =Table1[[#This Row],[Steps]]-C21 -> -900
A23: 3 | B23: 3.8.2017 | C23: 575 | D23: =Table1[[#This Row],[Steps]]-C22 -> -1221 | F23: Mean | G23: 3571.5806 | J23: Mean | K23: 3287.36
A24: 4 | B24: 4.8.2017 | C24: 294 | D24: =Table1[[#This Row],[Steps]]-C23 -> -281 | F24: Standard Error | G24: 970.17444 | J24: Standard Error | K24: 674.03567
A25: 5 | B25: 5.8.2017 | C25: 12975 | D25: =Table1[[#This Row],[Steps]]-C24 -> 12681 | F25: Median | G25: 1475 | J25: Median | K25: 1784.5
A26: 6 | B26: 6.8.2017 | C26: 2238 | D26: =Table1[[#This Row],[Steps]]-C25 -> -10737 | F26: Mode | G26: 0 | J26: Mode | K26: 0
A27: 7 | B27: 7.8.2017 | C27: 6760 | D27: =Table1[[#This Row],[Steps]]-C26 -> 4522 | F27: Standard Deviation | G27: 5401.7027 | J27: Standard Deviation | K27: 4766.1519
A28: 8 | B28: 8.8.2017 | C28: 21 | D28: =Table1[[#This Row],[Steps]]-C27 -> -6739 | F28: Sample Variance | G28: 29178392 | J28: Sample Variance | K28: 22716204
A29: 9 | B29: 9.8.2017 | C29: 0 | D29: =Table1[[#This Row],[Steps]]-C28 -> -21 | F29: Kurtosis | G29: 9.1226667 | J29: Kurtosis | K29: 9.7317078
A30: 10 | B30: 10.8.2017 | C30: 1475 | D30: =Table1[[#This Row],[Steps]]-C29 -> 1475 | F30: Skewness | G30: 2.7309986 | J30: Skewness | K30: 2.7512321
A31: 11 | B31: 11.8.2017 | C31: 0 | D31: =Table1[[#This Row],[Steps]]-C30 -> -1475 | F31: Range | G31: 25825 | J31: Range | K31: 25825
A32: 12 | B32: 12.8.2017 | C32: 0 | D32: =Table1[[#This Row],[Steps]]-C31 -> 0 | F32: Minimum | G32: 0 | J32: Minimum | K32: 0
A33: 13 | B33: 13.8.2017 | C33: 680 | D33: =Table1[[#This Row],[Steps]]-C32 -> 680 | F33: Maximum | G33: 25825 | J33: Maximum | K33: 25825
A34: 14 | B34: 14.8.2017 | C34: 3763 | D34: =Table1[[#This Row],[Steps]]-C33 -> 3083 | F34: Sum | G34: 110719 | J34: Sum | K34: 164368
... A38: 18 | B38: 18.8.2017 | C38: 897 | D38: =Table1[[#This Row],[Steps]]-C37 -> 612 | F38: Confidence Level(95.0%) | G38: 1981.3605 | J38: Confidence Level(95.0%) | K38: 1354.5254
A39: 19 | B39: 19.8.2017 | C39: 59 | D39: =Table1[[#This Row],[Steps]]-C38 -> -838
A40: 20 | B40: 20.8.2017 | C40: 0 | D40: =Table1[[#This Row],[Steps]]-C39 -> -59
A41: 21 | B41: 21.8.2017 | C41: 1003 | D41: =Table1[[#This Row],[Steps]]-C40 -> 1003
A42: 22 | B42: 22.8.2017 | C42: 1438 | D42: =Table1[[#This Row],[Steps]]-C41 -> 435
A43: 23 | B43: 23.8.2017 | C43: 6621 | D43: =Table1[[#This Row],[Steps]]-C42 -> 5183
...

Sheet 2018
A1: Number | B1: Day | C1: Steps | D1: Difference | E1: Colories | F1: Difference of C | G1: Distance | H1: Difference of D | I1: Time | J1: Difference of time
A2: 1 | B2: 43101 | C2: 12997 | D2: =Table13[[#This Row],[Steps]]-C1 -> #VALUE! | E2: 499.1 | F2: =Table13[[#This Row],[Colories]]-E1 -> #VALUE! | G2: 9.34 | H2: =Table13[[#This Row],[Distance]]-G1 -> #VALUE! | I2: 112 | J2: =Table13[[#This Row],[Time]]-I1 -> #VALUE! | K2: Steps | M2: Calories | N2: Distance | O2: Time | R2: Steps | S2: Calories | T2: Distance | U2: Time
A3: 2 | B3: 43102 | C3: 9018 | D3: =Table13[[#This Row],[Steps]]-C2 -> -3979 | E3: 348.2 | F3: =Table13[[#This Row],[Colories]]-E2 -> -150.9 | G3: 6.49 | H3: =Table13[[#This Row],[Distance]]-G2 -> -2.85 | I3: 81 | J3: =Table13[[#This Row],[Time]]-I2 -> -31 | Q3: Mean | R3: =AVERAGE($C$1:$C$366) -> 9856.6932 | S3: =AVERAGE($E$1:$E$366) -> 383.69644 | T3: =AVERAGE($G$1:$G$366) -> 7.1223562 | U3: =AVERAGE($I$1:$I$366) -> 89.493151
A4: 3 | B4: 43103 | C4: 11450 | D4: =Table13[[#This Row],[Steps]]-C3 -> 2432 | E4: 442.3 | F4: =Table13[[#This Row],[Colories]]-E3 -> 94.1 | G4: 8.24 | H4: =Table13[[#This Row],[Distance]]-G3 -> 1.75 | I4: 102 | J4: =Table13[[#This Row],[Time]]-I3 -> 21 | K4: Mean | L4: 8247.9032 | M4: 313.79 | N4: 5.824 | O4: 73.935484 | Q4: Standard Error | R4: =SQRT(VAR($C$1:$C$366)/COUNT($C$1:$C$366)) -> 259.83584 | S4: =SQRT(VAR($E$1:$E$366)/COUNT($E$1:$E$366)) -> 10.053709 | T4: =SQRT(VAR($G$1:$G$366)/COUNT($G$1:$G$366)) -> 0.18667661 | U4: =SQRT(VAR($I$1:$I$366)/COUNT($I$1:$I$366)) -> 2.3745306
A5: 4 | B5: 43104 | C5: 10032 | D5: =Table13[[#This Row],[Steps]]-C4 -> -1418 | E5: 385 | F5: =Table13[[#This Row],[Colories]]-E4 -> -57.3 | G5: 7.22 | H5: =Table13[[#This Row],[Distance]]-G4 -> -1.02 | I5: 85 | J5: =Table13[[#This Row],[Time]]-I4 -> -17 | K5: Standard Error | L5: 800.64975 | M5: 31.203979 | N5: 0.58431207 | O5: 7.077138 | Q5: Mode | R5: =MODE($C$1:$C$366) -> 6004 | S5: =MODE($E$1:$E$366) -> 524.9 | T5: =MODE($G$1:$G$366) -> 4.33 | U5: =MODE($I$1:$I$366) -> 61
A6: 5 | B6: 43105 | C6: 11435 | D6: =Table13[[#This Row],[Steps]]-C5 -> 1403 | E6: 449.5 | F6: =Table13[[#This Row],[Colories]]-E5 -> 64.5 | G6: 8.23 | H6: =Table13[[#This Row],[Distance]]-G5 -> 1.01 | I6: 108 | J6: =Table13[[#This Row],[Time]]-I5 -> 23 | K6: Median | L6: 7292 | M6: 268.9 | N6: 5.04 | O6: 64 | Q6: Median | R6: =MEDIAN($C$1:$C$366) -> 9580 | S6: =MEDIAN($E$1:$E$366) -> 370.2 | T6: =MEDIAN($G$1:$G$366) -> 6.9 | U6: =MEDIAN($I$1:$I$366) -> 86
A7: 6 | B7: 43106 | C7: 8438 | D7: =Table13[[#This Row],[Steps]]-C6 -> -2997 | E7: 337 | F7: =Table13[[#This Row],[Colories]]-E6 -> -112.5 | G7: 6.08 | H7: =Table13[[#This Row],[Distance]]-G6 -> -2.15 | I7: 85 | J7: =Table13[[#This Row],[Time]]-I6 -> -23 | K7: Mode | L7: =#N/A -> #N/A | M7: =#N/A -> #N/A | N7: =#N/A -> #N/A | O7: 112 | Q7: First Quartile | R7: =QUARTILE($C$1:$C$366, 1) -> 6601 | S7: =QUARTILE($E$1:$E$366, 1) -> 257.9 | T7: =QUARTILE($G$1:$G$366, 1) -> 4.8 | U7: =QUARTILE($I$1:$I$366, 1) -> 61
A8: 7 | B8: 43107 | C8: 10676 | D8: =Table13[[#This Row],[Steps]]-C7 -> 2238 | E8: 410.6 | F8: =Table13[[#This Row],[Colories]]-E7 -> 73.6 | G8: 7.69 | H8: =Table13[[#This Row],[Distance]]-G7 -> 1.61 | I8: 94 | J8: =Table13[[#This Row],[Time]]-I7 -> 9 | K8: Standard Deviation | L8: 4457.8292 | M8: 170.91123 | N8: 3.200409 | O8: 39.403837 | Q8: Third Quartile | R8: =QUARTILE($C$1:$C$366, 3) -> 12524 | S8: =QUARTILE($E$1:$E$366, 3) -> 484.5 | T8: =QUARTILE($G$1:$G$366, 3) -> 9.03 | U8: =QUARTILE($I$1:$I$366, 3) -> 112
A9: 8 | B9: 43108 | C9: 7292 | D9: =Table13[[#This Row],[Steps]]-C8 -> -3384 | E9: 280 | F9: =Table13[[#This Row],[Colories]]-E8 -> -130.6 | G9: 5.25 | H9: =Table13[[#This Row],[Distance]]-G8 -> -2.44 | I9: 64 | J9: =Table13[[#This Row],[Time]]-I8 -> -30 | K9: Sample Variance | L9: 19872241 | M9: 29210.649 | N9: 10.242618 | O9: 1552.6624 | Q9: Variance | R9: =VAR($C$1:$C$366) -> 24642852 | S9: =VAR($E$1:$E$366) -> 36893.13 | T9: =VAR($G$1:$G$366) -> 12.719577 | U9: =VAR($I$1:$I$366) -> 2058.0144
A10: 9 | B10: 43109 | C10: 20021 | D10: =Table13[[#This Row],[Steps]]-C9 -> 12729 | E10: 770.2 | F10: =Table13[[#This Row],[Colories]]-E9 -> 490.2 | G10: 14.42 | H10: =Table13[[#This Row],[Distance]]-G9 -> 9.17 | I10: 176 | J10: =Table13[[#This Row],[Time]]-I9 -> 112 | K10: Kurtosis | L10: 0.67833417 | M10: 0.91817099 | N10: 0.93453303 | O10: 0.5757302 | Q10: Standard Deviation | R10: =STDEV($C$1:$C$366) -> 4964.1567 | S10: =STDEV($E$1:$E$366) -> 192.07584 | T10: =STDEV($G$1:$G$366) -> 3.5664516 | U10: =STDEV($I$1:$I$366) -> 45.365343
A11: 10 | B11: 43110 | C11: 6080 | D11: =Table13[[#This Row],[Steps]]-C10 -> -13941 | E11: 233.8 | F11: =Table13[[#This Row],[Colories]]-E10 -> -536.4 | G11: 4.38 | H11: =Table13[[#This Row],[Distance]]-G10 -> -10.04 | I11: 52 | J11: =Table13[[#This Row],[Time]]-I10 -> -124 | K11: Skewness | L11: 0.59449505 | M11: 0.68134225 | N11: 0.69225046 | O11: 0.56668095 | Q11: Kurtosis | R11: =KURT($C$1:$C$366) -> 3.9709179 | S11: =KURT($E$1:$E$366) -> 4.3208627 | T11: =KURT($G$1:$G$366) -> 3.9878063 | U11: =KURT($I$1:$I$366) -> 5.4778867
A12: 11 | B12: 43111 | C12: 6008 | D12: =Table13[[#This Row],[Steps]]-C11 -> -72 | E12: 236.1 | F12: =Table13[[#This Row],[Colories]]-E11 -> 2.3 | G12: 4.33 | H12: =Table13[[#This Row],[Distance]]-G11 -> -0.05 | I12: 56 | J12: =Table13[[#This Row],[Time]]-I11 -> 4 | K12: Range | L12: 19813 | M12: 762 | N12: 14.27 | O12: 174 | Q12: Skewness | R12: =SKEW($C$1:$C$366) -> 1.0330093 | S12: =SKEW($E$1:$E$366) -> 1.0866034 | T12: =SKEW($G$1:$G$366) -> 1.0346259 | U12: =SKEW($I$1:$I$366) -> 1.2188799
A13: 12 | B13: 43112 | C13: 5712 | D13: =Table13[[#This Row],[Steps]]-C12 -> -296 | E13: 226.7 | F13: =Table13[[#This Row],[Colories]]-E12 -> -9.4 | G13: 4.11 | H13: =Table13[[#This Row],[Distance]]-G12 -> -0.22 | I13: 54 | J13: =Table13[[#This Row],[Time]]-I12 -> -2 | K13: Minimum | L13: 208 | M13: 8.2 | N13: 0.15 | O13: 2 | Q13: Range | R13: =MAX($C$1:$C$366)-MIN($C$1:$C$366) -> 38613 | S13: =MAX($E$1:$E$366)-MIN($E$1:$E$366) -> 1528.3 | T13: =MAX($G$1:$G$366)-MIN($G$1:$G$366) -> 27.81 | U13: =MAX($I$1:$I$366)-MIN($I$1:$I$366) -> 382
A14: 13 | B14: 43113 | C14: 4604 | D14: =Table13[[#This Row],[Steps]]-C13 -> -1108 | E14: 180.6 | F14: =Table13[[#This Row],[Colories]]-E13 -> -46.1 | G14: 3.31 | H14: =Table13[[#This Row],[Distance]]-G13 -> -0.8 | I14: 43 | J14: =Table13[[#This Row],[Time]]-I13 -> -11 | K14: Maximum | L14: 20021 | M14: 770.2 | N14: 14.42 | O14: 176 | Q14: Minimum | R14: =MIN($C$1:$C$366) -> 19 | S14: =MIN($E$1:$E$366) -> 0.8 | T14: =MIN($G$1:$G$366) -> 0.01 | U14: =MIN($I$1:$I$366) -> 0
A15: 14 | B15: 43114 | C15: 361 | D15: =Table13[[#This Row],[Steps]]-C14 -> -4243 | E15: 15 | F15: =Table13[[#This Row],[Colories]]-E14 -> -165.6 | G15: 0.26 | H15: =Table13[[#This Row],[Distance]]-G14 -> -3.05 | I15: 4 | J15: =Table13[[#This Row],[Time]]-I14 -> -39 | K15: Sum | L15: 255685 | M15: 9413.7 | N15: 174.72 | O15: 2292 | Q15: Maximum | R15: =MAX($C$1:$C$366) -> 38632 | S15: =MAX($E$1:$E$366) -> 1529.1 | T15: =MAX($G$1:$G$366) -> 27.82 | U15: =MAX($I$1:$I$366) -> 382
A16: 15 | B16: 43115 | C16: 6708 | D16: =Table13[[#This Row],[Steps]]-C15 -> 6347 | E16: 257.8 | F16: =Table13[[#This Row],[Colories]]-E15 -> 242.8 | G16: 4.83 | H16: =Table13[[#This Row],[Distance]]-G15 -> 4.57 | I16: 59 | J16: =Table13[[#This Row],[Time]]-I15 -> 55 | K16: Count | L16: 31 | M16: 30 | N16: 30 | O16: 31 | Q16: Sum | R16: =SUM($C$1:$C$366) -> 3597693 | S16: =SUM($E$1:$E$366) -> 140049.2 | T16: =SUM($G$1:$G$366) -> 2599.66 | U16: =SUM($I$1:$I$366) -> 32665
A17: 16 | B17: 43116 | C17: 9777 | D17: =Table13[[#This Row],[Steps]]-C16 -> 3069 | E17: 376.7 | F17: =Table13[[#This Row],[Colories]]-E16 -> 118.9 | G17: 7.04 | H17: =Table13[[#This Row],[Distance]]-G16 -> 2.21 | I17: 87 | J17: =Table13[[#This Row],[Time]]-I16 -> 28 | K17: Largest(1) | L17: 20021 | M17: 770.2 | N17: 14.42 | O17: 176 | Q17: Count | R17: =COUNT($C$1:$C$366) -> 365 | S17: =COUNT($E$1:$E$366) -> 365 | T17: =COUNT($G$1:$G$366) -> 365 | U17: =COUNT($I$1:$I$366) -> 365
A18: 17 | B18: 43117 | C18: 9430 | D18: =Table13[[#This Row],[Steps]]-C17 -> -347 | E18: 363.6 | F18: =Table13[[#This Row],[Colories]]-E17 -> -13.1 | G18: 6.79 | H18: =Table13[[#This Row],[Distance]]-G17 -> -0.25 | I18: 84 | J18: =Table13[[#This Row],[Time]]-I17 -> -3 | K18: Smallest(1) | L18: 208 | M18: 8.2 | N18: 0.15 | O18: 2
A19: 18 | B19: 43118 | C19: 6042 | D19: =Table13[[#This Row],[Steps]]-C18 -> -3388 | E19: 230.4 | F19: =Table13[[#This Row],[Colories]]-E18 -> -133.2 | G19: 4.35 | H19: =Table13[[#This Row],[Distance]]-G18 -> -2.44 | I19: 50 | J19: =Table13[[#This Row],[Time]]-I18 -> -34 | K19: Confidence Level(95,0%) | L19: 1635.1449 | M19: 63.819302 | N19: 1.1950524 | O19: 14.453444
A20: 19 | B20: 43119 | C20: 6351 | D20: =Table13[[#This Row],[Steps]]-C19 -> 309 | E20: 251.7 | F20: =Table13[[#This Row],[Colories]]-E19 -> 21.3 | G20: 4.57 | H20: =Table13[[#This Row],[Distance]]-G19 -> 0.22 | I20: 61 | J20: =Table13[[#This Row],[Time]]-I19 -> 11
A21: 20 | B21: 43120 | C21: 5218 | D21: =Table13[[#This Row],[Steps]]-C20 -> -1133 | E21: 206.8 | F21: =Table13[[#This Row],[Colories]]-E20 -> -44.9 | G21: 3.76 | H21: =Table13[[#This Row],[Distance]]-G20 -> -0.81 | I21: 51 | J21: =Table13[[#This Row],[Time]]-I20 -> -10
A22: 21 | B22: 43121 | C22: 208 | D22: =Table13[[#This Row],[Steps]]-C21 -> -5010 | E22: 8.2 | F22: =Table13[[#This Row],[Colories]]-E21 -> -198.6 | G22: 0.15 | H22: =Table13[[#This Row],[Distance]]-G21 -> -3.61 | I22: 2 | J22: =Table13[[#This Row],[Time]]-I21 -> -49
A23: 22 | B23: 43122 | C23: 8905 | D23: =Table13[[#This Row],[Steps]]-C22 -> 8697 | E23: 341.6 | F23: =Table13[[#This Row],[Colories]]-E22 -> 333.4 | G23: 6.41 | H23: =Table13[[#This Row],[Distance]]-G22 -> 6.26 | I23: 77 | J23: =Table13[[#This Row],[Time]]-I22 -> 75
A24: 23 | B24: 43123 | C24: 11164 | D24: =Table13[[#This Row],[Steps]]-C23 -> 2259 | E24: 430 | F24: =Table13[[#This Row],[Colories]]-E23 -> 88.4 | G24: 8.04 | H24: =Table13[[#This Row],[Distance]]-G23 -> 1.63 | I24: 98 | J24: =Table13[[#This Row],[Time]]-I23 -> 21
A25: 24 | B25: 43124 | C25: 3496 | D25: =Table13[[#This Row],[Steps]]-C24 -> -7668 | E25: 134.1 | F25: =Table13[[#This Row],[Colories]]-E24 -> -295.9 | G25: 2.52 | H25: =Table13[[#This Row],[Distance]]-G24 -> -5.52 | I25: 30 | J25: =Table13[[#This Row],[Time]]-I24 -> -68
A26: 25 | B26: 43125 | C26: 12432 | D26: =Table13[[#This Row],[Steps]]-C25 -> 8936 | E26: 480.2 | F26: =Table13[[#This Row],[Colories]]-E25 -> 346.1 | G26: 8.95 | H26: =Table13[[#This Row],[Distance]]-G25 -> 6.43 | I26: 112 | J26: =Table13[[#This Row],[Time]]-I25 -> 82
A27: 26 | B27: 43126 | C27: 5963 | D27: =Table13[[#This Row],[Steps]]-C26 -> -6469 | E27: 229.2 | F27: =Table13[[#This Row],[Colories]]-E26 -> -251 | G27: 4.29 | H27: =Table13[[#This Row],[Distance]]-G26 -> -4.66 | I27: 51 | J27: =Table13[[#This Row],[Time]]-I26 -> -61
A28: 27 | B28: 43127 | C28: 2881 | D28: =Table13[[#This Row],[Steps]]-C27 -> -3082 | E28: 117.1 | F28: =Table13[[#This Row],[Colories]]-E27 -> -112.1 | G28: 2.07 | H28: =Table13[[#This Row],[Distance]]-G27 -> -2.22 | I28: 30 | J28: =Table13[[#This Row],[Time]]-I27 -> -21
A29: 28 | B29: 43128 | C29: 4893 | D29: =Table13[[#This Row],[Steps]]-C28 -> 2012 | E29: 195.2 | F29: =Table13[[#This Row],[Colories]]-E28 -> 78.1 | G29: 3.52 | H29: =Table13[[#This Row],[Distance]]-G28 -> 1.45 | I29: 42 | J29: =Table13[[#This Row],[Time]]-I28 -> 12
A30: 29 | B30: 43129 | C30: 6004 | D30: =Table13[[#This Row],[Steps]]-C29 -> 1111 | E30: 233 | F30: =Table13[[#This Row],[Colories]]-E29 -> 37.8 | G30: 4.32 | H30: =Table13[[#This Row],[Distance]]-G29 -> 0.8 | I30: 53 | J30: =Table13[[#This Row],[Time]]-I29 -> 11
A31: 30 | B31: 43130 | C31: 17278 | D31: =Table13[[#This Row],[Steps]]-C30 -> 11274 | E31: 667.3 | F31: =Table13[[#This Row],[Colories]]-E30 -> 434.3 | G31: 12.44 | H31: =Table13[[#This Row],[Distance]]-G30 -> 8.12 | I31: 153 | J31: =Table13[[#This Row],[Time]]-I30 -> 100
A32: 31 | B32: 43131 | C32: 14811 | D32: =Table13[[#This Row],[Steps]]-C31 -> -2467 | E32: 575.8 | F32: =Table13[[#This Row],[Colories]]-E31 -> -91.5 | G32: 10.66 | H32: =Table13[[#This Row],[Distance]]-G31 -> -1.78 | I32: 136 | J32: =Table13[[#This Row],[Time]]-I31 -> -17
A33: 13 | B33: 43132 | C33: 7538 | D33: =Table13[[#This Row],[Steps]]-C32 -> -7273 | E33: 289 | F33: =Table13[[#This Row],[Colories]]-E32 -> -286.8 | G33: 5.43 | H33: =Table13[[#This Row],[Distance]]-G32 -> -5.23 | I33: 65 | J33: =Table13[[#This Row],[Time]]-I32 -> -71 | K33: February 2018 | L33: Steps | M33: Calories | N33: Distance | O33: Time
A34: 14 | B34: 43133 | C34: 9721 | D34: =Table13[[#This Row],[Steps]]-C33 -> 2183 | E34: 375.4 | F34: =Table13[[#This Row],[Colories]]-E33 -> 86.4 | G34: 7 | H34: =Table13[[#This Row],[Distance]]-G33 -> 1.57 | I34: 87 | J34: =Table13[[#This Row],[Time]]-I33 -> 22
A35: 15 | B35: 43134 | C35: 13284 | D35: =Table13[[#This Row],[Steps]]-C34 -> 3563 | E35: 518.4 | F35: =Table13[[#This Row],[Colories]]-E34 -> 143 | G35: 9.56 | H35: =Table13[[#This Row],[Distance]]-G34 -> 2.56 | I35: 125 | J35: =Table13[[#This Row],[Time]]-I34 -> 38 | K35: Mean | L35: 9305.1852 | M35: 360.58148 | N35: 6.6974074 | O35: 81.444444
A36: 16 | B36: 43135 | C36: 5738 | D36: =Table13[[#This Row],[Steps]]-C35 -> -7546 | E36: 221.8 | F36: =Table13[[#This Row],[Colories]]-E35 -> -296.6 | G36: 4.13 | H36: =Table13[[#This Row],[Distance]]-G35 -> -5.43 | I36: 50 | J36: =Table13[[#This Row],[Time]]-I35 -> -75 | K36: Standard Error | L36: 643.09121 | M36: 24.630206 | N36: 0.46343189 | O36: 6.3374555
A37: 17 | B37: 43136 | C37: 8346 | D37: =Table13[[#This Row],[Steps]]-C36 -> 2608 | E37: 319.2 | F37: =Table13[[#This Row],[Colories]]-E36 -> 97.4 | G37: 6.01 | H37: =Table13[[#This Row],[Distance]]-G36 -> 1.88 | I37: 71 | J37: =Table13[[#This Row],[Time]]-I36 -> 21 | K37: Median | L37: 9669 | M37: 375.4 | N37: 6.96 | O37: 86
A38: 18 | B38: 43137 | C38: 12111 | D38: =Table13[[#This Row],[Steps]]-C37 -> 3765 | E38: 464.9 | F38: =Table13[[#This Row],[Colories]]-E37 -> 145.7 | G38: 8.72 | H38: =Table13[[#This Row],[Distance]]-G37 -> 2.71 | I38: 104 | J38: =Table13[[#This Row],[Time]]-I37 -> 33 | K38: Mode | L38: =#N/A -> #N/A | M38: =#N/A -> #N/A | N38: 6.01 | O38: 98
A39: 19 | B39: 43138 | C39: 12821 | D39: =Table13[[#This Row],[Steps]]-C38 -> 710 | E39: 491.7 | F39: =Table13[[#This Row],[Colories]]-E38 -> 26.8 | G39: 9.23 | H39: =Table13[[#This Row],[Distance]]-G38 -> 0.51 | I39: 111 | J39: =Table13[[#This Row],[Time]]-I38 -> 7 | K39: Standard Deviation | L39: 3341.6 | M39: 127.98231 | N39: 2.4080627 | O39: 32.930385
A40: 20 | B40: 43139 | C40: 13702 | D40: =Table13[[#This Row],[Steps]]-C39 -> 881 | E40: 528.6 | F40: =Table13[[#This Row],[Colories]]-E39 -> 36.9 | G40: 9.87 | H40: =Table13[[#This Row],[Distance]]-G39 -> 0.64 | I40: 120 | J40: =Table13[[#This Row],[Time]]-I39 -> 9 | K40: Sample Variance | L40: 11166290 | M40: 16379.471 | N40: 5.7987661 | O40: 1084.4103
...

Sheet 2019
A1: Number | B1: Day | C1: Steps | D1: Difference | E1: Colories | F1: Difference of C | G1: Distance | H1: Difference of D | I1: Time | J1: Difference of time
A2: 1 | B2: 43466 | C2: 7034 | D2: =Table134[[#This Row],[Steps]]-C1 -> #VALUE! | E2: 280.3 | F2: =Table134[[#This Row],[Colories]]-E1 -> #VALUE! | G2: 5.06 | H2: =Table134[[#This Row],[Distance]]-G1 -> #VALUE! | I2: 68 | J2: =Table134[[#This Row],[Time]]-I1 -> #VALUE! | M2: Steps | N2: Calories | O2: Distance | P2: Time | S2: Steps | T2: Calories | U2: Distance | V2: Time
A3: 2 | B3: 43467 | C3: 16097 | D3: =Table134[[#This Row],[Steps]]-C2 -> 9063 | E3: 619.6 | F3: =Table134[[#This Row],[Colories]]-E2 -> 339.3 | G3: 11.59 | H3: =Table134[[#This Row],[Distance]]-G2 -> 6.53 | I3: 142 | J3: =Table134[[#This Row],[Time]]-I2 -> 74 | L3: Mean | M3: 7567.5484 | N3: 293.74839 | O3: 5.4487097 | P3: 68.741935 | R3: Mean | S3: =AVERAGE($C$1:$C$366) -> 11072.754 | T3: =AVERAGE($E$1:$E$366) -> 448.76215 | U3: =AVERAGE($G$1:$G$366) -> 7.9732873 | V3: =AVERAGE($I$1:$I$366) -> 106.16298
A4: 3 | B4: 43468 | C4: 8016 | D4: =Table134[[#This Row],[Steps]]-C3 -> -8081 | E4: 306.6 | F4: =Table134[[#This Row],[Colories]]-E3 -> -313 | G4: 5.77 | H4: =Table134[[#This Row],[Distance]]-G3 -> -5.82 | I4: 68 | J4: =Table134[[#This Row],[Time]]-I3 -> -74 | L4: Standard Error | M4: 765.36704 | N4: 29.262811 | O4: 0.55104197 | P4: 6.7000189 | R4: Standard Error | S4: =SQRT(VAR($C$1:$C$366)/COUNT($C$1:$C$366)) -> 312.8468 | T4: =SQRT(VAR($E$1:$E$366)/COUNT($E$1:$E$366)) -> 12.870777 | U4: =SQRT(VAR($G$1:$G$366)/COUNT($G$1:$G$366)) -> 0.22523452 | V4: =SQRT(VAR($I$1:$I$366)/COUNT($I$1:$I$366)) -> 3.0792069
A5: 4 | B5: 43469 | C5: 5968 | D5: =Table134[[#This Row],[Steps]]-C4 -> -2048 | E5: 231.9 | F5: =Table134[[#This Row],[Colories]]-E4 -> -74.7 | G5: 4.3 | H5: =Table134[[#This Row],[Distance]]-G4 -> -1.47 | I5: 55 | J5: =Table134[[#This Row],[Time]]-I4 -> -13 | L5: Median | M5: 7653 | N5: 299.2 | O5: 5.51 | P5: 71 | R5: Mode | S5: =MODE($C$1:$C$366) -> 0 | T5: =MODE($E$1:$E$366) -> 0 | U5: =MODE($G$1:$G$366) -> 0 | V5: =MODE($I$1:$I$366) -> 0
A6: 5 | B6: 43470 | C6: 6677 | D6: =Table134[[#This Row],[Steps]]-C5 -> 709 | E6: 258.2 | F6: =Table134[[#This Row],[Colories]]-E5 -> 26.3 | G6: 4.81 | H6: =Table134[[#This Row],[Distance]]-G5 -> 0.51 | I6: 60 | J6: =Table134[[#This Row],[Time]]-I5 -> 5 | L6: Mode | M6: =#N/A -> #N/A | N6: =#N/A -> #N/A | O6: 5.06 | P6: 68 | R6: Median | S6: =MEDIAN($C$1:$C$366) -> 10933 | T6: =MEDIAN($E$1:$E$366) -> 441.35 | U6: =MEDIAN($G$1:$G$366) -> 7.87 | V6: =MEDIAN($I$1:$I$366) -> 103
A7: 6 | B7: 43471 | C7: 7640 | D7: =Table134[[#This Row],[Steps]]-C6 -> 963 | E7: 299.2 | F7: =Table134[[#This Row],[Colories]]-E6 -> 41 | G7: 5.5 | H7: =Table134[[#This Row],[Distance]]-G6 -> 0.69 | I7: 73 | J7: =Table134[[#This Row],[Time]]-I6 -> 13 | L7: Standard Deviation | M7: 4261.3833 | N7: 162.92844 | O7: 3.0680719 | P7: 37.304126 | R7: First Quartile | S7: =QUARTILE($C$1:$C$366, 1) -> 7125.5 | T7: =QUARTILE($E$1:$E$366, 1) -> 285.975 | U7: =QUARTILE($G$1:$G$366, 1) -> 5.13 | V7: =QUARTILE($I$1:$I$366, 1) -> 69
A8: 7 | B8: 43472 | C8: 8177 | D8: =Table134[[#This Row],[Steps]]-C7 -> 537 | E8: 312.4 | F8: =Table134[[#This Row],[Colories]]-E7 -> 13.2 | G8: 5.89 | H8: =Table134[[#This Row],[Distance]]-G7 -> 0.39 | I8: 69 | J8: =Table134[[#This Row],[Time]]-I7 -> -4 | L8: Sample Variance | M8: 18159388 | N8: 26545.675 | O8: 9.4130649 | P8: 1391.5978 | R8: Third Quartile | S8: =QUARTILE($C$1:$C$366, 3) -> 14430.75 | T8: =QUARTILE($E$1:$E$366, 3) -> 577.35 | U8: =QUARTILE($G$1:$G$366, 3) -> 10.3925 | V8: =QUARTILE($I$1:$I$366, 3) -> 136
A9: 8 | B9: 43473 | C9: 8714 | D9: =Table134[[#This Row],[Steps]]-C8 -> 537 | E9: 334 | F9: =Table134[[#This Row],[Colories]]-E8 -> 21.6 | G9: 6.27 | H9: =Table134[[#This Row],[Distance]]-G8 -> 0.38 | I9: 75 | J9: =Table134[[#This Row],[Time]]-I8 -> 6 | L9: Kurtosis | M9: -0.35198853 | N9: -0.31686556 | O9: -0.35322254 | P9: -0.26940495 | R9: Variance | S9: =VAR($C$1:$C$366) -> 35430070 | T9: =VAR($E$1:$E$366) -> 59967.794 | U9: =VAR($G$1:$G$366) -> 18.364473 | V9: =VAR($I$1:$I$366) -> 3432.3085
A10: 9 | B10: 43474 | C10: 14935 | D10: =Table134[[#This Row],[Steps]]-C9 -> 6221 | E10: 575.7 | F10: =Table134[[#This Row],[Colories]]-E9 -> 241.7 | G10: 10.75 | H10: =Table134[[#This Row],[Distance]]-G9 -> 4.48 | I10: 134 | J10: =Table134[[#This Row],[Time]]-I9 -> 59 | L10: Skewness | M10: 0.065405486 | N10: 0.042845038 | O10: 0.064755095 | P10: -0.0090579534 | R10: Standard Deviation | S10: =STDEV($C$1:$C$366) -> 5952.3164 | T10: =STDEV($E$1:$E$366) -> 244.88323 | U10: =STDEV($G$1:$G$366) -> 4.2853789 | V10: =STDEV($I$1:$I$366) -> 58.585907
A11: 10 | B11: 43475 | C11: 11718 | D11: =Table134[[#This Row],[Steps]]-C10 -> -3217 | E11: 449 | F11: =Table134[[#This Row],[Colories]]-E10 -> -126.7 | G11: 8.44 | H11: =Table134[[#This Row],[Distance]]-G10 -> -2.31 | I11: 101 | J11: =Table134[[#This Row],[Time]]-I10 -> -33 | L11: Range | M11: 15853 | N11: 609.5 | O11: 11.41 | P11: 140 | R11: Kurtosis | S11: =KURT($C$1:$C$366) -> 1.8097609 | T11: =KURT($E$1:$E$366) -> 2.4449145 | U11: =KURT($G$1:$G$366) -> 1.8097786 | V11: =KURT($I$1:$I$366) -> 3.2947936
A12: 11 | B12: 43476 | C12: 7024 | D12: =Table134[[#This Row],[Steps]]-C11 -> -4694 | E12: 282.2 | F12: =Table134[[#This Row],[Colories]]-E11 -> -166.8 | G12: 5.06 | H12: =Table134[[#This Row],[Distance]]-G11 -> -3.38 | I12: 71 | J12: =Table134[[#This Row],[Time]]-I11 -> -30 | L12: Minimum | M12: 244 | N12: 10.1 | O12: 0.18 | P12: 2 | R12: Skewness | S12: =SKEW($C$1:$C$366) -> 0.78146534 | T12: =SKEW($E$1:$E$366) -> 0.94646687 | U12: =SKEW($G$1:$G$366) -> 0.78169697 | V12: =SKEW($I$1:$I$366) -> 1.1392627
A13: 12 | B13: 43477 | C13: 3269 | D13: =Table134[[#This Row],[Steps]]-C12 -> -3755 | E13: 129.6 | F13: =Table134[[#This Row],[Colories]]-E12 -> -152.6 | G13: 2.35 | H13: =Table134[[#This Row],[Distance]]-G12 -> -2.71 | I13: 32 | J13: =Table134[[#This Row],[Time]]-I12 -> -39 | L13: Maximum | M13: 16097 | N13: 619.6 | O13: 11.59 | P13: 142 | R13: Range | S13: =MAX($C$1:$C$366)-MIN($C$1:$C$366) -> 35974 | T13: =MAX($E$1:$E$366)-MIN($E$1:$E$366) -> 1515.1 | U13: =MAX($G$1:$G$366)-MIN($G$1:$G$366) -> 25.9 | V13: =MAX($I$1:$I$366)-MIN($I$1:$I$366) -> 371
A14: 13 | B14: 43478 | C14: 929 | D14: =Table134[[#This Row],[Steps]]-C13 -> -2340 | E14: 37.6 | F14: =Table134[[#This Row],[Colories]]-E13 -> -92 | G14: 0.67 | H14: =Table134[[#This Row],[Distance]]-G13 -> -1.68 | I14: 9 | J14: =Table134[[#This Row],[Time]]-I13 -> -23 | L14: Sum | M14: 234594 | N14: 9106.2 | O14: 168.91 | P14: 2131 | R14: Minimum | S14: =MIN($C$1:$C$366) -> 0 | T14: =MIN($E$1:$E$366) -> 0 | U14: =MIN($G$1:$G$366) -> 0 | V14: =MIN($I$1:$I$366) -> 0
A15: 14 | B15: 43479 | C15: 244 | D15: =Table134[[#This Row],[Steps]]-C14 -> -685 | E15: 10.1 | F15: =Table134[[#This Row],[Colories]]-E14 -> -27.5 | G15: 0.18 | H15: =Table134[[#This Row],[Distance]]-G14 -> -0.49 | I15: 2 | J15: =Table134[[#This Row],[Time]]-I14 -> -7 | L15: Count | M15: 31 | N15: 31 | O15: 31 | P15: 31 | R15: Maximum | S15: =MAX($C$1:$C$366) -> 35974 | T15: =MAX($E$1:$E$366) -> 1515.1 | U15: =MAX($G$1:$G$366) -> 25.9 | V15: =MAX($I$1:$I$366) -> 371
A16: 15 | B16: 43480 | C16: 516 | D16: =Table134[[#This Row],[Steps]]-C15 -> 272 | E16: 21.9 | F16: =Table134[[#This Row],[Colories]]-E15 -> 11.8 | G16: 0.37 | H16: =Table134[[#This Row],[Distance]]-G15 -> 0.19 | I16: 6 | J16: =Table134[[#This Row],[Time]]-I15 -> 4 | L16: Largest(1) | M16: 16097 | N16: 619.6 | O16: 11.59 | P16: 142 | R16: Sum | S16: =SUM($C$1:$C$366) -> 4008337 | T16: =SUM($E$1:$E$366) -> 162451.9 | U16: =SUM($G$1:$G$366) -> 2886.33 | V16: =SUM($I$1:$I$366) -> 38431
A17: 16 | B17: 43481 | C17: 3596 | D17: =Table134[[#This Row],[Steps]]-C16 -> 3080 | E17: 149 | F17: =Table134[[#This Row],[Colories]]-E16 -> 127.1 | G17: 2.59 | H17: =Table134[[#This Row],[Distance]]-G16 -> 2.22 | I17: 39 | J17: =Table134[[#This Row],[Time]]-I16 -> 33 | L17: Smallest(1) | M17: 244 | N17: 10.1 | O17: 0.18 | P17: 2 | R17: Count | S17: =COUNT($C$1:$C$366) -> 362 | T17: =COUNT($E$1:$E$366) -> 362 | U17: =COUNT($G$1:$G$366) -> 362 | V17: =COUNT($I$1:$I$366) -> 362
A18: 17 | B18: 43482 | C18: 8261 | D18: =Table134[[#This Row],[Steps]]-C17 -> 4665 | E18: 326 | F18: =Table134[[#This Row],[Colories]]-E17 -> 177 | G18: 5.95 | H18: =Table134[[#This Row],[Distance]]-G17 -> 3.36 | I18: 80 | J18: =Table134[[#This Row],[Time]]-I17 -> 41 | L18: Confidence Level(95,0%) | M18: 1563.088 | N18: 59.762633 | O18: 1.1253778 | P18: 13.683264
A19: 18 | B19: 43483 | C19: 1102 | D19: =Table134[[#This Row],[Steps]]-C18 -> -7159 | E19: 46.2 | F19: =Table134[[#This Row],[Colories]]-E18 -> -279.8 | G19: 0.79 | H19: =Table134[[#This Row],[Distance]]-G18 -> -5.16 | I19: 12 | J19: =Table134[[#This Row],[Time]]-I18 -> -68
A20: 19 | B20: 43484 | C20: 1738 | D20: =Table134[[#This Row],[Steps]]-C19 -> 636 | E20: 67 | F20: =Table134[[#This Row],[Colories]]-E19 -> 20.8 | G20: 1.25 | H20: =Table134[[#This Row],[Distance]]-G19 -> 0.46 | I20: 15 | J20: =Table134[[#This Row],[Time]]-I19 -> 3
A21: 20 | B21: 43485 | C21: 7425 | D21: =Table134[[#This Row],[Steps]]-C20 -> 5687 | E21: 295.3 | F21: =Table134[[#This Row],[Colories]]-E20 -> 228.3 | G21: 5.35 | H21: =Table134[[#This Row],[Distance]]-G20 -> 4.1 | I21: 74 | J21: =Table134[[#This Row],[Time]]-I20 -> 59
A22: 21 | B22: 43486 | C22: 12745 | D22: =Table134[[#This Row],[Steps]]-C21 -> 5320 | E22: 489.8 | F22: =Table134[[#This Row],[Colories]]-E21 -> 194.5 | G22: 9.18 | H22: =Table134[[#This Row],[Distance]]-G21 -> 3.83 | I22: 113 | J22: =Table134[[#This Row],[Time]]-I21 -> 39
A23: 22 | B23: 43487 | C23: 8178 | D23: =Table134[[#This Row],[Steps]]-C22 -> -4567 | E23: 313.4 | F23: =Table134[[#This Row],[Colories]]-E22 -> -176.4 | G23: 5.89 | H23: =Table134[[#This Row],[Distance]]-G22 -> -3.29 | I23: 71 | J23: =Table134[[#This Row],[Time]]-I22 -> -42
A24: 23 | B24: 43488 | C24: 12136 | D24: =Table134[[#This Row],[Steps]]-C23 -> 3958 | E24: 466.2 | F24: =Table134[[#This Row],[Colories]]-E23 -> 152.8 | G24: 8.74 | H24: =Table134[[#This Row],[Distance]]-G23 -> 2.85 | I24: 107 | J24: =Table134[[#This Row],[Time]]-I23 -> 36
A25: 24 | B25: 43489 | C25: 10130 | D25: =Table134[[#This Row],[Steps]]-C24 -> -2006 | E25: 389.1 | F25: =Table134[[#This Row],[Colories]]-E24 -> -77.1 | G25: 7.29 | H25: =Table134[[#This Row],[Distance]]-G24 -> -1.45 | I25: 89 | J25: =Table134[[#This Row],[Time]]-I24 -> -18
A26: 25 | B26: 43490 | C26: 15187 | D26: =Table134[[#This Row],[Steps]]-C25 -> 5057 | E26: 585.4 | F26: =Table134[[#This Row],[Colories]]-E25 -> 196.3 | G26: 10.93 | H26: =Table134[[#This Row],[Distance]]-G25 -> 3.64 | I26: 136 | J26: =Table134[[#This Row],[Time]]-I25 -> 47
A27: 26 | B27: 43491 | C27: 4555 | D27: =Table134[[#This Row],[Steps]]-C26 -> -10632 | E27: 177.8 | F27: =Table134[[#This Row],[Colories]]-E26 -> -407.6 | G27: 3.28 | H27: =Table134[[#This Row],[Distance]]-G26 -> -7.65 | I27: 40 | J27: =Table134[[#This Row],[Time]]-I26 -> -96
A28: 27 | B28: 43492 | C28: 6393 | D28: =Table134[[#This Row],[Steps]]-C27 -> 1838 | E28: 253.1 | F28: =Table134[[#This Row],[Colories]]-E27 -> 75.3 | G28: 4.6 | H28: =Table134[[#This Row],[Distance]]-G27 -> 1.32 | I28: 62 | J28: =Table134[[#This Row],[Time]]-I27 -> 22
A29: 28 | B29: 43493 | C29: 9591 | D29: =Table134[[#This Row],[Steps]]-C28 -> 3198 | E29: 372.1 | F29: =Table134[[#This Row],[Colories]]-E28 -> 119 | G29: 6.91 | H29: =Table134[[#This Row],[Distance]]-G28 -> 2.31 | I29: 88 | J29: =Table134[[#This Row],[Time]]-I28 -> 26
A30: 29 | B30: 43494 | C30: 8414 | D30: =Table134[[#This Row],[Steps]]-C29 -> -1177 | E30: 325.3 | F30: =Table134[[#This Row],[Colories]]-E29 -> -46.8 | G30: 6.06 | H30: =Table134[[#This Row],[Distance]]-G29 -> -0.85 | I30: 76 | J30: =Table134[[#This Row],[Time]]-I29 -> -12
... A33: 13 | B33: 43497 | C33: 16006 | D33: =Table134[[#This Row],[Steps]]-C32 -> 8353 | E33: 626.1 | F33: =Table134[[#This Row],[Colories]]-E32 -> 329.3 | G33: 11.52 | H33: =Table134[[#This Row],[Distance]]-G32 -> 6.01 | I33: 152 | J33: =Table134[[#This Row],[Time]]-I32 -> 82
A34: 14 | B34: 43498 | C34: 12965 | D34: =Table134[[#This Row],[Steps]]-C33 -> -3041 | E34: 506.5 | F34: =Table134[[#This Row],[Colories]]-E33 -> -119.6 | G34: 9.33 | H34: =Table134[[#This Row],[Distance]]-G33 -> -2.19 | I34: 119 | J34: =Table134[[#This Row],[Time]]-I33 -> -33 | M34: Steps | N34: Calories | O34: Distance | P34: Time
A35: 15 | B35: 43499 | C35: 12507 | D35: =Table134[[#This Row],[Steps]]-C34 -> -458 | E35: 485.3 | F35: =Table134[[#This Row],[Colories]]-E34 -> -21.2 | G35: 9.01 | H35: =Table134[[#This Row],[Distance]]-G34 -> -0.32 | I35: 115 | J35: =Table134[[#This Row],[Time]]-I34 -> -4 | L35: Mean | M35: 10667.607 | N35: 414.07857 | O35: 7.6817857 | P35: 97.642857
A36: 16 | B36: 43500 | C36: 10570 | D36: =Table134[[#This Row],[Steps]]-C35 -> -1937 | E36: 415.5 | F36: =Table134[[#This Row],[Colories]]-E35 -> -69.8 | G36: 7.61 | H36: =Table134[[#This Row],[Distance]]-G35 -> -1.4 | I36: 100 | J36: =Table134[[#This Row],[Time]]-I35 -> -15 | L36: Standard Error | M36: 748.66391 | N36: 29.047751 | O36: 0.53910813 | P36: 6.9259527
A37: 17 | B37: 43501 | C37: 11372 | D37: =Table134[[#This Row],[Steps]]-C36 -> 802 | E37: 439.9 | F37: =Table134[[#This Row],[Colories]]-E36 -> 24.4 | G37: 8.19 | H37: =Table134[[#This Row],[Distance]]-G36 -> 0.58 | I37: 103 | J37: =Table134[[#This Row],[Time]]-I36 -> 3 | L37: Median | M37: 10971 | N37: 427.7 | O37: 7.9 | P37: 101.5
A38: 18 | B38: 43502 | C38: 11896 | D38: =Table134[[#This Row],[Steps]]-C37 -> 524 | E38: 461.8 | F38: =Table134[[#This Row],[Colories]]-E37 -> 21.9 | G38: 8.57 | H38: =Table134[[#This Row],[Distance]]-G37 -> 0.38 | I38: 109 | J38: =Table134[[#This Row],[Time]]-I37 -> 6 | L38: Mode | M38: =#N/A -> #N/A | N38: =#N/A -> #N/A | O38: =#N/A -> #N/A | P38: 109
A39: 19 | B39: 43503 | C39: 7966 | D39: =Table134[[#This Row],[Steps]]-C38 -> -3930 | E39: 308.2 | F39: =Table134[[#This Row],[Colories]]-E38 -> -153.6 | G39: 5.74 | H39: =Table134[[#This Row],[Distance]]-G38 -> -2.83 | I39: 72 | J39: =Table134[[#This Row],[Time]]-I38 -> -37 | L39: Standard Deviation | M39: 3961.5571 | N39: 153.70625 | O39: 2.8526921 | P39: 36.648697
A40: 20 | B40: 43504 | C40: 6626 | D40: =Table134[[#This Row],[Steps]]-C39 -> -1340 | E40: 256.3 | F40: =Table134[[#This Row],[Colories]]-E39 -> -51.9 | G40: 4.77 | H40: =Table134[[#This Row],[Distance]]-G39 -> -0.97 | I40: 60 | J40: =Table134[[#This Row],[Time]]-I39 -> -12 | L40: Sample Variance | M40: 15693934 | N40: 23625.612 | O40: 8.1378522 | P40: 1343.127
A41: 21 | B41: 43505 | C41: 14037 | D41: =Table134[[#This Row],[Steps]]-C40 -> 7411 | E41: 551.8 | F41: =Table134[[#This Row],[Colories]]-E40 -> 295.5 | G41: 10.11 | H41: =Table134[[#This Row],[Distance]]-G40 -> 5.34 | I41: 136 | J41: =Table134[[#This Row],[Time]]-I40 -> 76 | L41: Kurtosis | M41: 0.061998543 | N41: 0.012420652 | O41: 0.060462577 | P41: -0.098277498
A42: 22 | B42: 43506 | C42: 3912 | D42: =Table134[[#This Row],[Steps]]-C41 -> -10125 | E42: 158.2 | F42: =Table134[[#This Row],[Colories]]-E41 -> -393.6 | G42: 2.82 | H42: =Table134[[#This Row],[Distance]]-G41 -> -7.29 | I42: 41 | J42: =Table134[[#This Row],[Time]]-I41 -> -95 | L42: Skewness | M42: -0.53006 | N42: -0.51110997 | O42: -0.52947683 | P42: -0.44258206
...

Sheet 2020
A1: Number | B1: Day | C1: Steps | D1: Difference | E1: Colories | F1: Difference of C | G1: Distance | H1: Difference of D | I1: Time | J1: Difference of time
A2: 1 | B2: 43831 | C2: 7392 | D2: - | E2: 306.4 | F2: - | G2: 5.32 | H2: - | I2: 73 | J2: - | L2: Steps | M2: Colories | N2: Distance | O2: Time
A3: 2 | B3: 43832 | C3: 3298 | D3: =C3-C2 -> -4094 | E3: 137.5 | F3: =E3-E2 -> -168.9 | G3: 2.37 | H3: =G3-G2 -> -2.95 | I3: 32 | J3: =I3-I2 -> -41 | K3: Mean | L3: =AVERAGE($C$2:$C$32) -> 7946.6774 | M3: =AVERAGE($E$1:$E$32) -> 329.70645 | N3: =AVERAGE($G$2:$G$32) -> 5.7209677 | O3: =AVERAGE($I$2:$I$32) -> 77.741935
A4: 3 | B4: 43833 | C4: 7385 | D4: =C4-C3 -> 4087 | E4: 306.3 | F4: =E4-E3 -> 168.8 | G4: 5.32 | H4: =G4-G3 -> 2.95 | I4: 73 | J4: =I4-I3 -> 41 | K4: Standard Error | L4: =SQRT(VAR($C$2:$C$32)/COUNT($C$2:$C$32)) -> 868.40178 | M4: =SQRT(VAR($E$1:$E$32)/COUNT($E$1:$E$32)) -> 35.449731 | N4: =SQRT(VAR($G$2:$G$32)/COUNT($G$2:$G$32)) -> 0.62545817 | O4: =SQRT(VAR($I$2:$I$32)/COUNT($I$2:$I$32)) -> 8.2540271
A5: 4 | B5: 43834 | C5: 10426 | D5: =C5-C4 -> 3041 | E5: 428.6 | F5: =E5-E4 -> 122.3 | G5: 7.51 | H5: =G5-G4 -> 2.19 | I5: 98 | J5: =I5-I4 -> 25 | K5: Mode | L5: =MODE($C$2:$C$32) -> #VALUE! | M5: =MODE($E$1:$E$32) -> #VALUE! | N5: =MODE($G$2:$G$32) -> 5.32 | O5: =MODE($I$2:$I$32) -> 73
A6: 5 | B6: 43835 | C6: 2415 | D6: =C6-C5 -> -8011 | E6: 110.9 | F6: =E6-E5 -> -317.7 | G6: 1.74 | H6: =G6-G5 -> -5.77 | I6: 29 | J6: =I6-I5 -> -69 | K6: Median | L6: =MEDIAN($C$2:$C$32) -> 7385 | M6: =MEDIAN($E$1:$E$32) -> 306.3 | N6: =MEDIAN($G$2:$G$32) -> 5.32 | O6: =MEDIAN($I$2:$I$32) -> 73
A7: 6 | B7: 43836 | C7: 2019 | D7: =C7-C6 -> -396 | E7: 87.8 | F7: =E7-E6 -> -23.1 | G7: 1.45 | H7: =G7-G6 -> -0.29 | I7: 22 | J7: =I7-I6 -> -7 | K7: First Quartile | L7: =QUARTILE($C$2:$C$32, 1) -> 4061.5 | M7: =QUARTILE($E$1:$E$32, 1) -> 165.3 | N7: =QUARTILE($G$2:$G$32, 1) -> 2.925 | O7: =QUARTILE($I$2:$I$32, 1) -> 39
A8: 7 | B8: 43837 | C8: 12783 | D8: =C8-C7 -> 10764 | E8: 524.8 | F8: =E8-E7 -> 437 | G8: 9.2 | H8: =G8-G7 -> 7.75 | I8: 122 | J8: =I8-I7 -> 100 | K8: Third Quartile | L8: =QUARTILE($C$2:$C$32, 3) -> 11128.5 | M8: =QUARTILE($E$1:$E$32, 3) -> 463.85 | N8: =QUARTILE($G$2:$G$32, 3) -> 8.015 | O8: =QUARTILE($I$2:$I$32, 3) -> 111
A9: 8 | B9: 43838 | C9: 13738 | D9: =C9-C8 -> 955 | E9: 558.8 | F9: =E9-E8 -> 34 | G9: 9.89 | H9: =G9-G8 -> 0.69 | I9: 128 | J9: =I9-I8 -> 6 | K9: Variance | L9: =VAR($C$2:$C$32) -> 23377771 | M9: =VAR($E$1:$E$32) -> 38957.185 | N9: =VAR($G$2:$G$32) -> 12.127136 | O9: =VAR($I$2:$I$32) -> 2111.9978
A10: 9 | B10: 43839 | C10: 5493 | D10: =C10-C9 -> -8245 | E10: 231 | F10: =E10-E9 -> -327.8 | G10: 3.95 | H10: =G10-G9 -> -5.94 | I10: 56 | J10: =I10-I9 -> -72 | K10: Standard Deviation | L10: =STDEV($C$2:$C$32) -> 4835.0565 | M10: =STDEV($E$1:$E$32) -> 197.37575 | N10: =STDEV($G$2:$G$32) -> 3.4824037 | O10: =STDEV($I$2:$I$32) -> 45.956478
A11: 10 | B11: 43840 | C11: 7253 | D11: =C11-C10 -> 1760 | E11: 296.4 | F11: =E11-E10 -> 65.4 | G11: 5.22 | H11: =G11-G10 -> 1.27 | I11: 68 | J11: =I11-I10 -> 12 | K11: Kurtosis | L11: =KURT($C$2:$C$32) -> -0.65419067 | M11: =KURT($E$1:$E$32) -> -0.61520964 | N11: =KURT($G$2:$G$32) -> -0.65362882 | O11: =KURT($I$2:$I$32) -> -0.54762961
A12: 11 | B12: 43841 | C12: 11480 | D12: =C12-C11 -> 4227 | E12: 469.7 | F12: =E12-E11 -> 173.3 | G12: 8.27 | H12: =G12-G11 -> 3.05 | I12: 109 | J12: =I12-I11 -> 41 | K12: Skewness | L12: =SKEW($C$2:$C$32) -> 0.60028516 | M12: =SKEW($E$1:$E$32) -> 0.60327482 | N12: =SKEW($G$2:$G$32) -> 0.60037289 | O12: =SKEW($I$2:$I$32) -> 0.61056209
A13: 12 | B13: 43842 | C13: 4205 | D13: =C13-C12 -> -7275 | E13: 169.7 | F13: =E13-E12 -> -300 | G13: 3.03 | H13: =G13-G12 -> -5.24 | I13: 38 | J13: =I13-I12 -> -71 | K13: Range | L13: =MAX($C$2:$C$32)-MIN($C$2:$C$32) -> 17211 | M13: =MAX($E$1:$E$32)-MIN($E$1:$E$32) -> 704.8 | N13: =MAX($G$2:$G$32)-MIN($G$2:$G$32) -> 12.4 | O13: =MAX($I$2:$I$32)-MIN($I$2:$I$32) -> 164
A14: 13 | B14: 43843 | C14: 17371 | D14: =C14-C13 -> 13166 | E14: 721.7 | F14: =E14-E13 -> 552 | G14: 12.51 | H14: =G14-G13 -> 9.48 | I14: 172 | J14: =I14-I13 -> 134 | K14: Minimum | L14: =MIN($C$2:$C$32) -> 713 | M14: =MIN($E$1:$E$32) -> 33.9 | N14: =MIN($G$2:$G$32) -> 0.51 | O14: =MIN($I$2:$I$32) -> 9
A15: 14 | B15: 43844 | C15: 3918 | D15: =C15-C14 -> -13453 | E15: 160.9 | F15: =E15-E14 -> -560.8 | G15: 2.82 | H15: =G15-G14 -> -9.69 | I15: 37 | J15: =I15-I14 -> -135 | K15: Maximum | L15: =MAX($C$2:$C$32) -> 17924 | M15: =MAX($E$1:$E$32) -> 738.7 | N15: =MAX($G$2:$G$32) -> 12.91 | O15: =MAX($I$2:$I$32) -> 173
A16: 15 | B16: 43845 | C16: 7726 | D16: =C16-C15 -> 3808 | E16: 317.2 | F16: =E16-E15 -> 156.3 | G16: 5.56 | H16: =G16-G15 -> 2.74 | I16: 74 | J16: =I16-I15 -> 37 | K16: Sum | L16: =SUM($C$2:$C$32) -> 246347 | M16: =SUM($E$1:$E$32) -> 10220.9 | N16: =SUM($G$2:$G$32) -> 177.35 | O16: =SUM($I$2:$I$32) -> 2410
A17: 16 | B17: 43846 | C17: 8123 | D17: =C17-C16 -> 397 | E17: 331.8 | F17: =E17-E16 -> 14.6 | G17: 5.85 | H17: =G17-G16 -> 0.29 | I17: 76 | J17: =I17-I16 -> 2 | K17: Count | L17: =COUNT($C$2:$C$32) -> 31 | M17: =COUNT($E$1:$E$32) -> 31 | N17: =COUNT($G$2:$G$32) -> 31 | O17: =COUNT($I$2:$I$32) -> 31
A18: 17 | B18: 43847 | C18: 14058 | D18: =C18-C17 -> 5935 | E18: 574.3 | F18: =E18-E17 -> 242.5 | G18: 10.12 | H18: =G18-G17 -> 4.27 | I18: 132 | J18: =I18-I17 -> 56
A19: 18 | B19: 43848 | C19: 3847 | D19: =C19-C18 -> -10211 | E19: 158.4 | F19: =E19-E18 -> -415.9 | G19: 2.77 | H19: =G19-G18 -> -7.35 | I19: 36 | J19: =I19-I18 -> -96
A20: 19 | B20: 43849 | C20: 713 | D20: =C20-C19 -> -3134 | E20: 33.9 | F20: =E20-E19 -> -124.5 | G20: 0.51 | H20: =G20-G19 -> -2.26 | I20: 9 | J20: =I20-I19 -> -27
A21: 20 | B21: 43850 | C21: 3617 | D21: =C21-C20 -> 2904 | E21: 156.7 | F21: =E21-E20 -> 122.8 | G21: 2.6 | H21: =G21-G20 -> 2.09 | I21: 40 | J21: =I21-I20 -> 31
A22: 21 | B22: 43851 | C22: 8344 | D22: =C22-C21 -> 4727 | E22: 356.1 | F22: =E22-E21 -> 199.4 | G22: 6.01 | H22: =G22-G21 -> 3.41 | I22: 87 | J22: =I22-I21 -> 47
A23: 22 | B23: 43852 | C23: 16291 | D23: =C23-C22 -> 7947 | E23: 672.1 | F23: =E23-E22 -> 316 | G23: 11.73 | H23: =G23-G22 -> 5.72 | I23: 159 | J23: =I23-I22 -> 72
A24: 23 | B24: 43853 | C24: 4794 | D24: =C24-C23 -> -11497 | E24: 195.6 | F24: =E24-E23 -> -476.5 | G24: 3.45 | H24: =G24-G23 -> -8.28 | I24: 44 | J24: =I24-I23 -> -115
A25: 24 | B25: 43854 | C25: 10777 | D25: =C25-C24 -> 5983 | E25: 458 | F25: =E25-E24 -> 262.4 | G25: 7.76 | H25: =G25-G24 -> 4.31 | I25: 113 | J25: =I25-I24 -> 69
A26: 25 | B26: 43855 | C26: 5256 | D26: =C26-C25 -> -5521 | E26: 250.8 | F26: =E26-E25 -> -207.2 | G26: 3.78 | H26: =G26-G25 -> -3.98 | I26: 70 | J26: =I26-I25 -> -43
A27: 26 | B27: 43856 | C27: 2165 | D27: =C27-C26 -> -3091 | E27: 89.2 | F27: =E27-E26 -> -161.6 | G27: 1.56 | H27: =G27-G26 -> -2.22 | I27: 21 | J27: =I27-I26 -> -49
A28: 27 | B28: 43857 | C28: 17924 | D28: =C28-C27 -> 15759 | E28: 738.7 | F28: =E28-E27 -> 649.5 | G28: 12.91 | H28: =G28-G27 -> 11.35 | I28: 173 | J28: =I28-I27 -> 152
A29: 28 | B29: 43858 | C29: 14627 | D29: =C29-C28 -> -3297 | E29: 595.9 | F29: =E29-E28 -> -142.8 | G29: 10.53 | H29: =G29-G28 -> -2.38 | I29: 137 | J29: =I29-I28 -> -36
... A32: 31 | B32: 43861 | C32: 5656 | D32: =C32-C31 -> -2649 | E32: 242.2 | F32: =E32-E31 -> -96.7 | G32: 4.07 | H32: =G32-G31 -> -1.91 | I32: 60 | J32: =I32-I31 -> -17
A33: 32 | B33: 43862 | C33: 19449 | D33: =C33-C32 -> 13793 | E33: 835.7 | F33: =E33-E32 -> 593.5 | G33: 14 | H33: =G33-G32 -> 9.93 | I33: 211 | J33: =I33-I32 -> 151 | L33: Steps | M33: Colories | N33: Distance | O33: Time
A34: 33 | B34: 43863 | C34: 25099 | D34: =C34-C33 -> 5650 | E34: 1074.9 | F34: =E34-E33 -> 239.2 | G34: 18.07 | H34: =G34-G33 -> 4.07 | I34: 270 | J34: =I34-I33 -> 59 | K34: Mean | L34: =AVERAGE($C$33:$C$61) -> 7782.1379 | M34: =AVERAGE($E$33:$E$61) -> 332.61379 | N34: =AVERAGE($G$33:$G$61) -> 5.6027586 | O34: =AVERAGE($I$33:$I$61) -> 81.103448
A35: 34 | B35: 43864 | C35: 4834 | D35: =C35-C34 -> -20265 | E35: 202.4 | F35: =E35-E34 -> -872.5 | G35: 3.48 | H35: =G35-G34 -> -14.59 | I35: 48 | J35: =I35-I34 -> -222 | K35: Standard Error | L35: =SQRT(VAR($C$33:$C$61)/COUNT($C$33:$C$61)) -> 1097.2951 | M35: =SQRT(VAR($E$33:$E$61)/COUNT($E$33:$E$61)) -> 46.730436 | N35: =SQRT(VAR($G$33:$G$61)/COUNT($G$33:$G$61)) -> 0.79002399 | O35: =SQRT(VAR($I$33:$I$61)/COUNT($I$33:$I$61)) -> 11.880806
A36: 35 | B36: 43865 | C36: 9142 | D36: =C36-C35 -> 4308 | E36: 380.9 | F36: =E36-E35 -> 178.5 | G36: 6.58 | H36: =G36-G35 -> 3.1 | I36: 90 | J36: =I36-I35 -> 42 | K36: Mode | L36: =MODE($C$33:$C$61) -> #VALUE! | M36: =MODE($E$33:$E$61) -> 178.1 | N36: =MODE($G$33:$G$61) -> 5.68 | O36: =MODE($I$33:$I$61) -> 64
A37: 36 | B37: 43866 | C37: 4069 | D37: =C37-C36 -> -5073 | E37: 168.4 | F37: =E37-E36 -> -212.5 | G37: 2.93 | H37: =G37-G36 -> -3.65 | I37: 40 | J37: =I37-I36 -> -50 | K37: Median | L37: =MEDIAN($C$33:$C$61) -> 6017 | M37: =MEDIAN($E$33:$E$61) -> 258.8 | N37: =MEDIAN($G$33:$G$61) -> 4.33 | O37: =MEDIAN($I$33:$I$61) -> 65
A38: 37 | B38: 43867 | C38: 2769 | D38: =C38-C37 -> -1300 | E38: 178.1 | F38: =E38-E37 -> 9.7 | G38: 1.99 | H38: =G38-G37 -> -0.94 | I38: 27 | J38: =I38-I37 -> -13 | K38: First Quartile | L38: =QUARTILE($C$33:$C$61, 1) -> 4352 | M38: =QUARTILE($E$33:$E$61, 1) -> 178.1 | N38: =QUARTILE($G$33:$G$61, 1) -> 3.13 | O38: =QUARTILE($I$33:$I$61, 1) -> 41
A39: 38 | B39: 43868 | C39: 4352 | D39: =C39-C38 -> 1583 | E39: 178.1 | F39: =E39-E38 -> 0 | G39: 3.13 | H39: =G39-G38 -> 1.14 | I39: 41 | J39: =I39-I38 -> 14 | K39: Third Quartile | L39: =QUARTILE($C$33:$C$61, 3) -> 9142 | M39: =QUARTILE($E$33:$E$61, 3) -> 381.1 | N39: =QUARTILE($G$33:$G$61, 3) -> 6.58 | O39: =QUARTILE($I$33:$I$61, 3) -> 90
A40: 39 | B40: 43869 | C40: 5354 | D40: =C40-C39 -> 1002 | E40: 227.3 | F40: =E40-E39 -> 49.2 | G40: 3.85 | H40: =G40-G39 -> 0.72 | I40: 55 | J40: =I40-I39 -> 14 | K40: Variance | L40: =VAR($C$33:$C$61) -> 34917639 | M40: =VAR($E$33:$E$61) -> 63328.277 | N40: =VAR($G$33:$G$61) -> 18.099999 | O40: =VAR($I$33:$I$61) -> 4093.4532
A41: 40 | B41: 43870 | C41: 5961 | D41: =C41-C40 -> 607 | E41: 258 | F41: =E41-E40 -> 30.7 | G41: 4.29 | H41: =G41-G40 -> 0.44 | I41: 64 | J41: =I41-I40 -> 9 | K41: Standard Deviation | L41: =STDEV($C$33:$C$61) -> 5909.1149 | M41: =STDEV($E$33:$E$61) -> 251.6511 | N41: =STDEV($G$33:$G$61) -> 4.2544094 | O41: =STDEV($I$33:$I$61) -> 63.9801
A42: 41 | B42: 43871 | C42: 9302 | D42: =C42-C41 -> 3341 | E42: 382.6 | F42: =E42-E41 -> 124.6 | G42: 6.7 | H42: =G42-G41 -> 2.41 | I42: 89 | J42: =I42-I41 -> 25 | K42: Kurtosis | L42: =KURT($C$33:$C$61) -> 2.3136064 | M42: =KURT($E$33:$E$61) -> 2.6708203 | N42: =KURT($G$33:$G$61) -> 2.3134279 | O42: =KURT($I$33:$I$61) -> 3.0604425
...

Sheet 2021
A1: Number | B1: Day | C1: Steps | D1: Difference | E1: Calories | F1: Difference of C | G1: Distance | H1: Difference of D | I1: Time | J1: Difference of time | L1: Steps | M1: Calories | N1: Distance | O1: Time
A2: 1 | B2: 44197 | C2: 2713 | D2: =C1-C2 -> #VALUE! | E2: 124.5 | F2: =E1-E2 -> #VALUE! | G2: 1.95 | H2: =G2-G1 -> #VALUE! | I2: 33 | J2: =I1-I2 -> #VALUE! | K2: Mean | L2: =AVERAGE($C$1:$C$32) -> 4574.4839 | M2: =AVERAGE($E$1:$E$32) -> 203.92581 | N2: =AVERAGE($G$1:$G$32) -> 3.293871 | O2: =AVERAGE($I$1:$I$32) -> 52.645161
A3: 2 | B3: 44198 | C3: 795 | D3: =C2-C3 -> 1918 | E3: 36.4 | F3: =E2-E3 -> 88.1 | G3: 0.57 | H3: =G3-G2 -> -1.38 | I3: 9 | J3: =I2-I3 -> 24 | K3: Standard Error | L3: =SQRT(VAR($C$1:$C$32)/COUNT($C$1:$C$32)) -> 808.07641 | M3: =SQRT(VAR($E$1:$E$32)/COUNT($E$1:$E$32)) -> 34.528427 | N3: =SQRT(VAR($G$1:$G$32)/COUNT($G$1:$G$32)) -> 0.58178474 | O3: =SQRT(VAR($I$1:$I$32)/COUNT($I$1:$I$32)) -> 8.6434198
A4: 3 | B4: 44199 | C4: 757 | D4: =C3-C4 -> 38 | E4: 35.8 | F4: =E3-E4 -> 0.6 | G4: 0.55 | H4: =G4-G3 -> -0.02 | I4: 9 | J4: =I3-I4 -> 0 | K4: Mode | L4: =MODE($C$1:$C$32) -> 2262 | M4: =MODE($E$1:$E$32) -> #VALUE! | N4: =MODE($G$1:$G$32) -> 1.63 | O4: =MODE($I$1:$I$32) -> 25
A5: 4 | B5: 44200 | C5: 4400 | D5: =C4-C5 -> -3643 | E5: 196.6 | F5: =E4-E5 -> -160.8 | G5: 3.17 | H5: =G5-G4 -> 2.62 | I5: 51 | J5: =I4-I5 -> -42 | K5: Median | L5: =MEDIAN($C$1:$C$32) -> 2733 | M5: =MEDIAN($E$1:$E$32) -> 134.7 | N5: =MEDIAN($G$1:$G$32) -> 1.97 | O5: =MEDIAN($I$1:$I$32) -> 37
A6: 5 | B6: 44201 | C6: 2220 | D6: =C5-C6 -> 2180 | E6: 97 | F6: =E5-E6 -> 99.6 | G6: 1.6 | H6: =G6-G5 -> -1.57 | I6: 25 | J6: =I5-I6 -> 26 | K6: First Quartile | L6: =QUARTILE($C$1:$C$32, 1) -> 1845 | M6: =QUARTILE($E$1:$E$32, 1) -> 88.95 | N6: =QUARTILE($G$1:$G$32, 1) -> 1.325 | O6: =QUARTILE($I$1:$I$32, 1) -> 24.5
A7: 6 | B7: 44202 | C7: 1923 | D7: =C6-C7 -> 297 | E7: 91.1 | F7: =E6-E7 -> 5.9 | G7: 1.38 | H7: =G7-G6 -> -0.22 | I7: 25 | J7: =I6-I7 -> 0 | K7: Third Quartile | L7: =QUARTILE($C$1:$C$32, 3) -> 5337.5 | M7: =QUARTILE($E$1:$E$32, 3) -> 234.85 | N7: =QUARTILE($G$1:$G$32, 3) -> 3.845 | O7: =QUARTILE($I$1:$I$32, 3) -> 60
A8: 7 | B8: 44203 | C8: 2262 | D8: =C7-C8 -> -339 | E8: 106.7 | F8: =E7-E8 -> -15.6 | G8: 1.63 | H8: =G8-G7 -> 0.25 | I8: 29 | J8: =I7-I8 -> -4 | K8: Variance | L8: =VAR($C$1:$C$32) -> 20242612 | M8: =VAR($E$1:$E$32) -> 36958.581 | N8: =VAR($G$1:$G$32) -> 10.492678 | O8: =VAR($I$1:$I$32) -> 2315.9699
A9: 8 | B9: 44204 | C9: 2817 | D9: =C8-C9 -> -555 | E9: 134.7 | F9: =E8-E9 -> -28 | G9: 2.03 | H9: =G9-G8 -> 0.4 | I9: 37 | J9: =I8-I9 -> -8 | K9: Standard Deviation | L9: =STDEV($C$1:$C$32) -> 4499.1791 | M9: =STDEV($E$1:$E$32) -> 192.24615 | N9: =STDEV($G$1:$G$32) -> 3.2392403 | O9: =STDEV($I$1:$I$32) -> 48.124525
A10: 9 | B10: 44205 | C10: 1184 | D10: =C9-C10 -> 1633 | E10: 57.6 | F10: =E9-E10 -> 77.1 | G10: 0.85 | H10: =G10-G9 -> -1.18 | I10: 16 | J10: =I9-I10 -> 21 | K10: Kurtosis | L10: =KURT($C$1:$C$32) -> 3.3982453 | M10: =KURT($E$1:$E$32) -> 3.7462619 | N10: =KURT($G$1:$G$32) -> 3.3969787 | O10: =KURT($I$1:$I$32) -> 4.2743676
A11: 10 | B11: 44206 | C11: 1508 | D11: =C10-C11 -> -324 | E11: 73.4 | F11: =E10-E11 -> -15.8 | G11: 1.09 | H11: =G11-G10 -> 0.24 | I11: 20 | J11: =I10-I11 -> -4 | K11: Skewness | L11: =SKEW($C$1:$C$32) -> 1.9363532 | M11: =SKEW($E$1:$E$32) -> 1.975955 | N11: =SKEW($G$1:$G$32) -> 1.9360778 | O11: =SKEW($I$1:$I$32) -> 2.0306687
A12: 11 | B12: 44207 | C12: 6615 | D12: =C11-C12 -> -5107 | E12: 289.4 | F12: =E11-E12 -> -216 | G12: 4.76 | H12: =G12-G11 -> 3.67 | I12: 74 | J12: =I11-I12 -> -54 | K12: Range | L12: =MAX($C$1:$C$32)-MIN($C$1:$C$32) -> 18325 | M12: =MAX($E$1:$E$32)-MIN($E$1:$E$32) -> 809.1 | N12: =MAX($G$1:$G$32)-MIN($G$1:$G$32) -> 13.19 | O12: =MAX($I$1:$I$32)-MIN($I$1:$I$32) -> 211
A13: 12 | B13: 44208 | C13: 3916 | D13: =C12-C13 -> 2699 | E13: 177.7 | F13: =E12-E13 -> 111.7 | G13: 2.82 | H13: =G13-G12 -> -1.94 | I13: 47 | J13: =I12-I13 -> 27 | K13: Minimum | L13: =MIN($C$1:$C$32) -> 566 | M13: =MIN($E$1:$E$32) -> 25.5 | N13: =MIN($G$1:$G$32) -> 0.41 | O13: =MIN($I$1:$I$32) -> 6
A14: 13 | B14: 44209 | C14: 1592 | D14: =C13-C14 -> 2324 | E14: 73.5 | F14: =E13-E14 -> 104.2 | G14: 1.15 | H14: =G14-G13 -> -1.67 | I14: 19 | J14: =I13-I14 -> 28 | K14: Maximum | L14: =MAX($C$1:$C$32) -> 18891 | M14: =MAX($E$1:$E$32) -> 834.6 | N14: =MAX($G$1:$G$32) -> 13.6 | O14: =MAX($I$1:$I$32) -> 217
A15: 14 | B15: 44210 | C15: 2706 | D15: =C14-C15 -> -1114 | E15: 130.8 | F15: =E14-E15 -> -57.3 | G15: 1.95 | H15: =G15-G14 -> 0.8 | I15: 36 | J15: =I14-I15 -> -17 | K15: Sum | L15: =SUM($C$1:$C$32) -> 141809 | M15: =SUM($E$1:$E$32) -> 6321.7 | N15: =SUM($G$1:$G$32) -> 102.11 | O15: =SUM($I$1:$I$32) -> 1632
A16: 15 | B16: 44211 | C16: 4841 | D16: =C15-C16 -> -2135 | E16: 210.8 | F16: =E15-E16 -> -80 | G16: 3.49 | H16: =G16-G15 -> 1.54 | I16: 53 | J16: =I15-I16 -> -17 | K16: Count | L16: =COUNT($C$1:$C$32) -> 31 | M16: =COUNT($E$1:$E$32) -> 31 | N16: =COUNT($G$1:$G$32) -> 31 | O16: =COUNT($I$1:$I$32) -> 31
A17: 16 | B17: 44212 | C17: 3375 | D17: =C16-C17 -> 1466 | E17: 172 | F17: =E16-E17 -> 38.8 | G17: 2.43 | H17: =G17-G16 -> -1.06 | I17: 50 | J17: =I16-I17 -> 3
A18: 17 | B18: 44213 | C18: 2733 | D18: =C17-C18 -> 642 | E18: 137 | F18: =E17-E18 -> 35 | G18: 1.97 | H18: =G18-G17 -> -0.46 | I18: 39 | J18: =I17-I18 -> 11
A19: 18 | B19: 44214 | C19: 7524 | D19: =C18-C19 -> -4791 | E19: 333.6 | F19: =E18-E19 -> -196.6 | G19: 5.42 | H19: =G19-G18 -> 3.45 | I19: 87 | J19: =I18-I19 -> -48
A20: 19 | B20: 44215 | C20: 1892 | D20: =C19-C20 -> 5632 | E20: 92 | F20: =E19-E20 -> 241.6 | G20: 1.36 | H20: =G20-G19 -> -4.06 | I20: 25 | J20: =I19-I20 -> 62
A21: 20 | B21: 44216 | C21: 15524 | D21: =C20-C21 -> -13632 | E21: 670.8 | F21: =E20-E21 -> -578.8 | G21: 11.18 | H21: =G21-G20 -> 9.82 | I21: 168 | J21: =I20-I21 -> -143
A22: 21 | B22: 44217 | C22: 9319 | D22: =C21-C22 -> 6205 | E22: 396.3 | F22: =E21-E22 -> 274.5 | G22: 6.71 | H22: =G22-G21 -> -4.47 | I22: 98 | J22: =I21-I22 -> 70
A23: 22 | B23: 44218 | C23: 5834 | D23: =C22-C23 -> 3485 | E23: 258.9 | F23: =E22-E23 -> 137.4 | G23: 4.2 | H23: =G23-G22 -> -2.51 | I23: 67 | J23: =I22-I23 -> 31
A24: 23 | B24: 44219 | C24: 18891 | D24: =C23-C24 -> -13057 | E24: 834.6 | F24: =E23-E24 -> -575.7 | G24: 13.6 | H24: =G24-G23 -> 9.4 | I24: 217 | J24: =I23-I24 -> -150
A25: 24 | B25: 44220 | C25: 14365 | D25: =C24-C25 -> 4526 | E25: 599.9 | F25: =E24-E25 -> 234.7 | G25: 10.34 | H25: =G25-G24 -> -3.26 | I25: 143 | J25: =I24-I25 -> 74
A26: 25 | B26: 44221 | C26: 4341 | D26: =C25-C26 -> 10024 | E26: 176.9 | F26: =E25-E26 -> 423 | G26: 3.13 | H26: =G26-G25 -> -7.21 | I26: 40 | J26: =I25-I26 -> 103
A27: 26 | B27: 44222 | C27: 2262 | D27: =C26-C27 -> 2079 | E27: 110.3 | F27: =E26-E27 -> 66.6 | G27: 1.63 | H27: =G27-G26 -> -1.5 | I27: 31 | J27: =I26-I27 -> 9
A28: 27 | B28: 44223 | C28: 7973 | D28: =C27-C28 -> -5711 | E28: 345 | F28: =E27-E28 -> -234.7 | G28: 5.74 | H28: =G28-G27 -> 4.11 | I28: 87 | J28: =I27-I28 -> -56
... A32: 31 | B32: 44227 | C32: 1644 | D32: =C31-C32 -> -1078 | E32: 81.9 | F32: =E31-E32 -> -56.4 | G32: 1.18 | H32: =G32-G31 -> 0.77 | I32: 23 | J32: =I31-I32 -> -17
A33: 32 | B33: 44228 | C33: 9974 | D33: =C32-C33 -> -8330 | E33: 438.1 | F33: =E32-E33 -> -356.2 | G33: 7.18 | H33: =G33-G32 -> 6 | I33: 113 | J33: =I32-I33 -> -90 | L33: Steps | M33: Calories | N33: Distance | O33: Time
A34: 33 | B34: 44229 | C34: 8399 | D34: =C33-C34 -> 1575 | E34: 360.8 | F34: =E33-E34 -> 77.3 | G34: 6.05 | H34: =G34-G33 -> -1.13 | I34: 90 | J34: =I33-I34 -> 23 | K34: Mean | L34: =AVERAGE($C$33:$C$60) -> 6831.8214 | M34: =AVERAGE($E$33:$E$60) -> 299.82143 | N34: =AVERAGE($G$33:$G$60) -> 4.9192857 | O34: =AVERAGE($I$33:$I$60) -> 76.607143
A35: 34 | B35: 44230 | C35: 4745 | D35: =C34-C35 -> 3654 | E35: 216.3 | F35: =E34-E35 -> 144.5 | G35: 3.42 | H35: =G35-G34 -> -2.63 | I35: 57 | J35: =I34-I35 -> 33 | K35: Standard Error | L35: =SQRT(VAR($C$33:$C$60)/COUNT($C$33:$C$60)) -> 902.07121 | M35: =SQRT(VAR($E$33:$E$60)/COUNT($E$33:$E$60)) -> 37.723481 | N35: =SQRT(VAR($G$33:$G$60)/COUNT($G$33:$G$60)) -> 0.64961139 | O35: =SQRT(VAR($I$33:$I$60)/COUNT($I$33:$I$60)) -> 9.1793331
A36: 35 | B36: 44231 | C36: 2726 | D36: =C35-C36 -> 2019 | E36: 118.2 | F36: =E35-E36 -> 98.1 | G36: 1.96 | H36: =G36-G35 -> -1.46 | I36: 30 | J36: =I35-I36 -> 27 | K36: Mode | L36: =MODE($C$33:$C$60) -> #VALUE! | M36: =MODE($E$33:$E$60) -> #VALUE! | N36: =MODE($G$33:$G$60) -> #VALUE! | O36: =MODE($I$33:$I$60) -> 29
A37: 36 | B37: 44232 | C37: 7471 | D37: =C36-C37 -> -4745 | E37: 321.5 | F37: =E36-E37 -> -203.3 | G37: 5.38 | H37: =G37-G36 -> 3.42 | I37: 81 | J37: =I36-I37 -> -51 | K37: Median | L37: =MEDIAN($C$33:$C$60) -> 5499.5 | M37: =MEDIAN($E$33:$E$60) -> 254.65 | N37: =MEDIAN($G$33:$G$60) -> 3.96 | O37: =MEDIAN($I$33:$I$60) -> 68
A38: 37 | B38: 44233 | C38: 3280 | D38: =C37-C38 -> 4191 | E38: 154.4 | F38: =E37-E38 -> 167.1 | G38: 2.36 | H38: =G38-G37 -> -3.02 | I38: 42 | J38: =I37-I38 -> 39 | K38: First Quartile | L38: =QUARTILE($C$33:$C$60, 1) -> 3196.5 | M38: =QUARTILE($E$33:$E$60, 1) -> 142.5 | N38: =QUARTILE($G$33:$G$60, 1) -> 2.3 | O38: =QUARTILE($I$33:$I$60, 1) -> 36.25
A39: 38 | B39: 44234 | C39: 15771 | D39: =C38-C39 -> -12491 | E39: 690 | F39: =E38-E39 -> -535.6 | G39: 11.36 | H39: =G39-G38 -> 9 | I39: 178 | J39: =I38-I39 -> -136 | K39: Third Quartile | L39: =QUARTILE($C$33:$C$60, 3) -> 8491 | M39: =QUARTILE($E$33:$E$60, 3) -> 368.575 | N39: =QUARTILE($G$33:$G$60, 3) -> 6.115 | O39: =QUARTILE($I$33:$I$60, 3) -> 93.75
A40: 39 | B40: 44235 | C40: 5141 | D40: =C39-C40 -> 10630 | E40: 233.4 | F40: =E39-E40 -> 456.6 | G40: 3.7 | H40: =G40-G39 -> -7.66 | I40: 62 | J40: =I39-I40 -> 116 | K40: Variance | L40: =VAR($C$33:$C$60) -> 22784509 | M40: =VAR($E$33:$E$60) -> 39845.708 | N40: =VAR($G$33:$G$60) -> 11.815859 | O40: =VAR($I$33:$I$60) -> 2359.2844
A41: 40 | B41: 44236 | C41: 3333 | D41: =C40-C41 -> 1808 | E41: 146.2 | F41: =E40-E41 -> 87.2 | G41: 2.4 | H41: =G41-G40 -> -1.3 | I41: 37 | J41: =I40-I41 -> 25 | K41: Standard Deviation | L41: =STDEV($C$33:$C$60) -> 4773.3122 | M41: =STDEV($E$33:$E$60) -> 199.6139 | N41: =STDEV($G$33:$G$60) -> 3.4374204 | O41: =STDEV($I$33:$I$60) -> 48.572465
A42: 41 | B42: 44237 | C42: 2385 | D42: =C41-C42 -> 948 | E42: 108.4 | F42: =E41-E42 -> 37.8 | G42: 1.72 | H42: =G42-G41 -> -0.68 | I42: 29 | J42: =I41-I42 -> 8 | K42: Kurtosis | L42: =KURT($C$33:$C$60) -> 0.37747547 | M42: =KURT($E$33:$E$60) -> 0.17920058 | N42: =KURT($G$33:$G$60) -> 0.37719986 | O42: =KURT($I$33:$I$60) -> -0.035028051
A43: 42 | B43: 44238 | C43: 4291 | D43: =C42-C43 -> -1906 | E43: 203 | F43: =E42-E43 -> -94.6 | G43: 3.09 | H43: =G43-G42 -> 1.37 | I43: 56 | J43: =I42-I43 -> -27 | K43: Skewness | L43: =SKEW($C$33:$C$60) -> 1.0333586 | M43: =SKEW($E$33:$E$60) -> 0.94885479 | N43: =SKEW($G$33:$G$60) -> 1.0333983 | O43: =SKEW($I$33:$I$60) -> 0.84123257
...

Sheet 2022
A1: Number | B1: Day | C1: Steps | D1: Difference | E1: Calories | F1: Difference of C | G1: Distance | H1: Difference of D | I1: Time | J1: Difference of time
A2: 1 | B2: 44562 | C2: 7897 | D2: =C1-C2 -> #VALUE! | E2: 349.1 | F2: =E1-E2 -> #VALUE! | G2: 5.69 | H2: =G2-G1 -> #VALUE! | I2: 78 | J2: =I1-I2 -> #VALUE! | L2: Steps | M2: Calories | N2: Distance | O2: Time
A3: 2 | B3: 44563 | C3: 14960 | D3: =C2-C3 -> -7063 | E3: 644.4 | F3: =E2-E3 -> -295.3 | G3: 10.77 | H3: =G3-G2 -> 5.08 | I3: 139 | J3: =I2-I3 -> -61 | K3: Mean | L3: =AVERAGE($C$1:$C$32) -> 7869.8387 | M3: =AVERAGE($E$1:$E$32) -> 342.3 | N3: =AVERAGE($G$1:$G$32) -> 5.6670968 | O3: =AVERAGE($I$1:$I$32) -> 74.83871
A4: 3 | B4: 44564 | C4: 4681 | D4: =C3-C4 -> 10279 | E4: 206.4 | F4: =E3-E4 -> 438 | G4: 3.37 | H4: =G4-G3 -> -7.4 | I4: 47 | J4: =I3-I4 -> 92 | K4: Standard Error | L4: =SQRT(VAR($C$1:$C$32)/COUNT($C$1:$C$32)) -> 700.91532 | M4: =SQRT(VAR($E$1:$E$32)/COUNT($E$1:$E$32)) -> 30.22102 | N4: =SQRT(VAR($G$1:$G$32)/COUNT($G$1:$G$32)) -> 0.50477339 | O4: =SQRT(VAR($I$1:$I$32)/COUNT($I$1:$I$32)) -> 6.5638464
A5: 4 | B5: 44565 | C5: 13412 | D5: =C4-C5 -> -8731 | E5: 577.8 | F5: =E4-E5 -> -371.4 | G5: 9.66 | H5: =G5-G4 -> 6.29 | I5: 124 | J5: =I4-I5 -> -77 | K5: Mode | L5: =MODE($C$1:$C$32) -> #VALUE! | M5: =MODE($E$1:$E$32) -> #VALUE! | N5: =MODE($G$1:$G$32) -> 5.82 | O5: =MODE($I$1:$I$32) -> 52
A6: 5 | B6: 44566 | C6: 9159 | D6: =C5-C6 -> 4253 | E6: 392.2 | F6: =E5-E6 -> 185.6 | G6: 6.59 | H6: =G6-G5 -> -3.07 | I6: 82 | J6: =I5-I6 -> 42 | K6: Median | L6: =MEDIAN($C$1:$C$32) -> 7924 | M6: =MEDIAN($E$1:$E$32) -> 346.3 | N6: =MEDIAN($G$1:$G$32) -> 5.71 | O6: =MEDIAN($I$1:$I$32) -> 74
A7: 6 | B7: 44567 | C7: 6788 | D7: =C6-C7 -> 2371 | E7: 297.7 | F7: =E6-E7 -> 94.5 | G7: 4.89 | H7: =G7-G6 -> -1.7 | I7: 66 | J7: =I6-I7 -> 16 | K7: First Quartile | L7: =QUARTILE($C$1:$C$32, 1) -> 5638.5 | M7: =QUARTILE($E$1:$E$32, 1) -> 242.95 | N7: =QUARTILE($G$1:$G$32, 1) -> 4.06 | O7: =QUARTILE($I$1:$I$32, 1) -> 52
A8: 7 | B8: 44568 | C8: 8470 | D8: =C7-C8 -> -1682 | E8: 365.7 | F8: =E7-E8 -> -68 | G8: 6.1 | H8: =G8-G7 -> 1.21 | I8: 79 | J8: =I7-I8 -> -13 | K8: Third Quartile | L8: =QUARTILE($C$1:$C$32, 3) -> 9017.5 | M8: =QUARTILE($E$1:$E$32, 3) -> 388.45 | N8: =QUARTILE($G$1:$G$32, 3) -> 6.49 | O8: =QUARTILE($I$1:$I$32, 3) -> 85
A9: 8 | B9: 44569 | C9: 1448 | D9: =C8-C9 -> 7022 | E9: 66.2 | F9: =E8-E9 -> 299.5 | G9: 1.04 | H9: =G9-G8 -> -5.06 | I9: 15 | J9: =I8-I9 -> 64 | K9: Variance | L9: =VAR($C$1:$C$32) -> 15229751 | M9: =VAR($E$1:$E$32) -> 28312.612 | N9: =VAR($G$1:$G$32) -> 7.8986813 | O9: =VAR($I$1:$I$32) -> 1335.6065
